test_0 (__main__.lab2a.test_0)
[Lab 2] - [Investigation 1] - [Part 1] - variables & printing - Test for file creation: ./lab2a.py ... ok
test_1 (__main__.lab2a.test_1)
[Lab 2] - [Investigation 1] - [Part 1] - variables & printing - Test for errors running: ./lab2a.py ... /usr/lib/python3.12/subprocess.py:822: ResourceWarning: unclosed file <_io.TextIOWrapper name=3 encoding='UTF-8'>
  _cleanup()
ResourceWarning: Enable tracemalloc to get the object allocation traceback
FAIL

======================================================================
FAIL: test_1 (__main__.lab2a.test_1)
[Lab 2] - [Investigation 1] - [Part 1] - variables & printing - Test for errors running: ./lab2a.py
----------------------------------------------------------------------
Traceback (most recent call last):
  File "/home/nkaur526/ops445/lab2/./CheckLab2.py", line 55, in test_1
    self.assertEqual(return_code, 0, msg=error_output)
AssertionError: 1 != 0 : your program exited with an error (HINT: try running your program to see the error)

----------------------------------------------------------------------
Ran 2 tests in 0.079s

FAILED (failures=1)
OPS445 Lab Report - System Information for running ./CheckLab2.py
=================================================================
    User login name: nkaur526
    Git Email: nkaur526@myseneca.com
    Linux system name: nkaur526-mint
    Python executable: /usr/bin/python3
    Python version:  3.12.3 (main, Feb  4 2025, 14:48:35) [GCC 13.3.0]
    OS Platform: linux
    Working Directory: /home/nkaur526/ops445/lab2
    Start at: Fri May 23 10:29:16 2025
=================================================================
